Traceback (most recent call last):
  File "/Users/nbrenowitz/workspace/nvidia/earth2grid/.venv/lib/python3.12/site-packages/jupyter_cache/executors/utils.py", line 58, in single_nb_execution
    executenb(
  File "/Users/nbrenowitz/workspace/nvidia/earth2grid/.venv/lib/python3.12/site-packages/nbclient/client.py", line 1319, in execute
    return NotebookClient(nb=nb, resources=resources, km=km, **kwargs).execute()
           ^^^^^^^^^^^^^^^^^^^^^^^^^^^^^^^^^^^^^^^^^^^^^^^^^^^^^^^^^^^^^^^^^^^^^
  File "/Users/nbrenowitz/workspace/nvidia/earth2grid/.venv/lib/python3.12/site-packages/jupyter_core/utils/__init__.py", line 165, in wrapped
    return loop.run_until_complete(inner)
           ^^^^^^^^^^^^^^^^^^^^^^^^^^^^^^
  File "/Users/nbrenowitz/.local/share/uv/python/cpython-3.12.10-macos-aarch64-none/lib/python3.12/asyncio/base_events.py", line 691, in run_until_complete
    return future.result()
           ^^^^^^^^^^^^^^^
  File "/Users/nbrenowitz/workspace/nvidia/earth2grid/.venv/lib/python3.12/site-packages/nbclient/client.py", line 709, in async_execute
    await self.async_execute_cell(
  File "/Users/nbrenowitz/workspace/nvidia/earth2grid/.venv/lib/python3.12/site-packages/nbclient/client.py", line 1062, in async_execute_cell
    await self._check_raise_for_error(cell, cell_index, exec_reply)
  File "/Users/nbrenowitz/workspace/nvidia/earth2grid/.venv/lib/python3.12/site-packages/nbclient/client.py", line 918, in _check_raise_for_error
    raise CellExecutionError.from_cell_and_msg(cell, exec_reply_content)
nbclient.exceptions.CellExecutionError: An error occurred while executing the following cell:
------------------
#| label: setup
import matplotlib.pyplot as plt
import numpy as np
import torch

import earth2grid
from earth2grid import healpix

# Create a sample HealPIX grid
level = 3  # Resolution level (higher = finer resolution)
grid = healpix.Grid(level=level, pixel_order=healpix.PixelOrder.RING)
print(grid.lat[:5])
------------------

----- stderr -----

KeyboardInterrupt
------------------



